<mujoco model="robotiq_hand-e">
  <body name="hand_base">
    <geom type="mesh" rgba="0.1 0.1 0.1 1" mesh="hand-e"/>

    <body name="hande_left_finger" pos="0.045 -0.0105 0.099">
      <inertial pos="0.02262 -0.00759 0.00738" quat="0.871952 0.0369732 -0.211073 0.440205" mass="0.03804" diaginertia="1.22763e-05 1.22763e-05 1.22763e-05"/>
      <joint class="gripper" name="left_finger" pos="0 0 0" axis="-1 0 0" type="slide" />
      <geom name="left_finger" type="mesh" rgba="0.4 0.4 0.4 1" mesh="hand-e_finger" priority="1" solimp="0.95 0.99 0.001 0.5 2"/>
    </body>
    
    <body name="hande_right_finger" pos="-0.045 -0.0105  0.099">
      <inertial pos="-0.02262 0.00759 0.00738" quat="0.871952 -0.0369732 0.211073 0.440205" mass="0.03804" diaginertia="1.22763e-05 1.22763e-05 1.22763e-05"/>
      <joint class="gripper" name="right_finger" pos="0 0 0" axis="1 0 0" type="slide" range="0 0.025"/>
      <geom name="right_finger" type="mesh" rgba="1 1 1 1" mesh="hand-e_finger_cam" priority="1" solimp="0.95 0.99 0.001 0.5 2"/>
      <geom type="cylinder" pos="0.019 0.0105 0.065" quat="0.996 0 0.087 0" class="visual" rgba="0 0 0 1" size="0.003 0.01" />
      <camera name="gripper_cam" pos="0.025 0.0105 0.055" quat="-0.062 0.704 0.704 -0.062" />
    </body>
  </body>
</mujoco>
