<mujoco model="ur5">
  <body name="arm_base_link" pos="0 0.243 1.4" quat="-0.270 0.653 0.653 0.270">
    <inertial pos="0 0 0" mass="4" diaginertia="0.0072 0.00443333 0.00443333" />
    <geom type="mesh" mesh="arm_base" material="ur5_mat"/>
    <body name="shoulder_link" pos="0 0 0.089159">
      <inertial pos="0 0 0" mass="3.7" diaginertia="0.0102675 0.0102675 0.00666" />
      <joint name="shoulder_pan_joint" axis="0 0 1" />
      <geom type="mesh" mesh="shoulder" material="ur5_mat"/>
    <body name="upper_arm_link" pos="0 0.13585 0" quat="0.707107 0 0.707107 0">
        <inertial pos="0 0 0.28" mass="8.393" diaginertia="0.226891 0.226891 0.0151074" />
        <joint name="shoulder_lift_joint" /> 
        <geom type="mesh" mesh="upperarm" material="ur5_mat"/>
        <body name="forearm_link" pos="0 -0.1197 0.425">
          <inertial pos="0 0 0.25" mass="2.275" diaginertia="0.0494433 0.0494433 0.004095" />
          <joint name="elbow_joint" />
          <geom type="mesh" mesh="forearm" material="ur5_mat"/>
          <body name="wrist_1_link" pos="0 0 0.39225" quat="0.707107 0 0.707107 0">
            <inertial pos="0 0 0" quat="0.5 0.5 -0.5 0.5" mass="1.219" diaginertia="0.21942 0.111173 0.111173" />
            <joint name="wrist_1_joint" />
            <geom type="mesh" mesh="wrist1" material="ur5_mat"/>
            <body name="wrist_2_link" pos="0 0.093 0">
              <inertial pos="0 0 0" quat="0.5 0.5 -0.5 0.5" mass="1.219" diaginertia="0.21942 0.111173 0.111173" />
              <joint name="wrist_2_joint" axis="0 0 1" />
              <geom type="mesh" mesh="wrist2" material="ur5_mat"/>
              <body name="wrist_3_link" pos="0 0 0.09465">
                <inertial pos="0 0 0" quat="0.5 0.5 -0.5 0.5" mass="0.1879" diaginertia="0.033822 0.0171365 0.0171365" />
                <joint name="wrist_3_joint" />
                <geom type="mesh" mesh="wrist3" material="ur5_mat"/>
                <body name="hand_link" pos="0 0.08 0" quat=" 0.707 -0.707 0 0" >
                  <include file="hand_e.xml" />
                </body>
              </body>
            </body>
          </body> 
        </body>
      </body>
    </body>
  </body>
</mujoco>
